<sdf version="1.9">
  <model name="iris_5">
    <!-- Body pose awal diset 0.1 meter agar mulai dari tanah -->
    <pose>0 0 0.1 0 0 0</pose>

    <!-- BAGIAN UTAMA (MAIN BODY) -->
    <link name="base_link">
      <enable_wind>true</enable_wind>
      <inertial>
        <pose>0 0 0 0 0 0</pose>
        <mass>1.0</mass>  <!-- HARUS SAMA DENGAN quadrotor_params.yaml -->
        <inertia>
          <ixx>0.0081</ixx><iyy>0.0081</iyy><izz>0.0142</izz>
          <ixy>0</ixy><ixz>0</ixz><iyz>0</iyz>
        </inertia>
      </inertial>
      
      <!-- Box Tengah -->
      <visual name="body_visual">
        <geometry><box><size>0.15 0.15 0.05</size></box></geometry>
        <material><ambient>0.2 0.2 0.2 1</ambient><diffuse>0.2 0.2 0.2 1</diffuse></material>
      </visual>
      <collision name="body_collision">
        <geometry><box><size>0.15 0.15 0.15</size></box></geometry>
      </collision>

      <!-- Visual Lengan (Arms) -->
      <!-- Arm 1 (Kanan Depan) -->
      <visual name="arm_fr"><pose>0.1 -0.1 0 0 0 -0.785</pose><geometry><box><size>0.15 0.02 0.01</size></box></geometry><material><ambient>0.4 0.4 0.4 1</ambient></material></visual>
      <!-- Arm 2 (Kiri Belakang) -->
      <visual name="arm_bl"><pose>-0.1 0.1 0 0 0 -0.785</pose><geometry><box><size>0.15 0.02 0.01</size></box></geometry><material><ambient>0.4 0.4 0.4 1</ambient></material></visual>
      <!-- Arm 3 (Kiri Depan) -->
      <visual name="arm_fl"><pose>0.1 0.1 0 0 0 0.785</pose><geometry><box><size>0.15 0.02 0.01</size></box></geometry><material><ambient>0.4 0.4 0.4 1</ambient></material></visual>
      <!-- Arm 4 (Kanan Belakang) -->
      <visual name="arm_br"><pose>-0.1 -0.1 0 0 0 0.785</pose><geometry><box><size>0.15 0.02 0.01</size></box></geometry><material><ambient>0.4 0.4 0.4 1</ambient></material></visual>

      <!-- VIRTUAL LIDAR SENSOR (DI DALAM BASE_LINK) -->
      <visual name="lidar_visual">
        <pose>0 0 0 0 0 0</pose>
        <geometry><cylinder><radius>0.03</radius><length>0.04</length></cylinder></geometry>
        <material><ambient>0.1 0.1 0.1 1</ambient><diffuse>0.1 0.1 0.1 1</diffuse></material>
      </visual>



      <sensor name='gpu_lidar' type='gpu_lidar'>
        <pose>0 0 0 0 0 0</pose>
        <frame_id>iris_5/base_link</frame_id>
        <update_rate>10</update_rate>
        <ray>
          <scan>
            <horizontal>
              <samples>360</samples>
              <resolution>1</resolution>
              <min_angle>-3.14159</min_angle>
              <max_angle>3.14159</max_angle>
            </horizontal>
          </scan>
          <range>
            <min>0.1</min>
            <max>10.0</max>
            <resolution>0.01</resolution>
          </range>
        </ray>
        <always_on>1</always_on>
      </sensor>
    </link>

    <!-- BALING-BALING 0 (Depan Kanan, Berlawanan Arah Jarum Jam) -->
    <link name="rotor_0">
      <pose>0.15 -0.15 0.03 0 0 0</pose>
      <inertial><mass>0.005</mass><inertia><ixx>1e-5</ixx><iyy>1e-5</iyy><izz>1e-5</izz></inertia></inertial>
      <visual name="rotor_0_visual">
        <geometry><cylinder><radius>0.1</radius><length>0.005</length></cylinder></geometry>
        <!-- Warna Biru Transparan -->
        <material><ambient>0 0 1 0.5</ambient><diffuse>0 0 1 0.5</diffuse></material>
      </visual>
    </link>
    <joint name="rotor_0_joint" type="revolute">
      <child>rotor_0</child><parent>base_link</parent>
      <axis><xyz>0 0 1</xyz><limit><lower>-1e16</lower><upper>1e16</upper></limit><dynamics><damping>0.005</damping><friction>0.01</friction></dynamics></axis>
    </joint>

    <!-- BALING-BALING 1 (Belakang Kiri, Berlawanan Arah Jarum Jam) -->
    <link name="rotor_1">
      <pose>-0.15 0.15 0.03 0 0 0</pose>
      <inertial><mass>0.005</mass><inertia><ixx>1e-5</ixx><iyy>1e-5</iyy><izz>1e-5</izz></inertia></inertial>
      <visual name="rotor_1_visual">
        <geometry><cylinder><radius>0.1</radius><length>0.005</length></cylinder></geometry>
        <!-- Warna Merah Transparan -->
        <material><ambient>1 0 0 0.5</ambient><diffuse>1 0 0 0.5</diffuse></material>
      </visual>
    </link>
    <joint name="rotor_1_joint" type="revolute">
      <child>rotor_1</child><parent>base_link</parent>
      <axis><xyz>0 0 1</xyz><limit><lower>-1e16</lower><upper>1e16</upper></limit><dynamics><damping>0.005</damping><friction>0.01</friction></dynamics></axis>
    </joint>

    <!-- BALING-BALING 2 (Depan Kiri, Searah Jarum Jam) -->
    <link name="rotor_2">
      <pose>0.15 0.15 0.03 0 0 0</pose>
      <inertial><mass>0.005</mass><inertia><ixx>1e-5</ixx><iyy>1e-5</iyy><izz>1e-5</izz></inertia></inertial>
      <visual name="rotor_2_visual">
        <geometry><cylinder><radius>0.1</radius><length>0.005</length></cylinder></geometry>
        <material><ambient>0 0 1 0.5</ambient><diffuse>0 0 1 0.5</diffuse></material>
      </visual>
    </link>
    <joint name="rotor_2_joint" type="revolute">
      <child>rotor_2</child><parent>base_link</parent>
      <axis><xyz>0 0 1</xyz><limit><lower>-1e16</lower><upper>1e16</upper></limit><dynamics><damping>0.005</damping><friction>0.01</friction></dynamics></axis>
    </joint>

    <!-- BALING-BALING 3 (Belakang Kanan, Searah Jarum Jam) -->
    <link name="rotor_3">
      <pose>-0.15 -0.15 0.03 0 0 0</pose>
      <inertial><mass>0.005</mass><inertia><ixx>1e-5</ixx><iyy>1e-5</iyy><izz>1e-5</izz></inertia></inertial>
      <visual name="rotor_3_visual">
        <geometry><cylinder><radius>0.1</radius><length>0.005</length></cylinder></geometry>
        <material><ambient>1 0 0 0.5</ambient><diffuse>1 0 0 0.5</diffuse></material>
      </visual>
    </link>
    <joint name="rotor_3_joint" type="revolute">
      <child>rotor_3</child><parent>base_link</parent>
      <axis><xyz>0 0 1</xyz><limit><lower>-1e16</lower><upper>1e16</upper></limit><dynamics><damping>0.005</damping><friction>0.01</friction></dynamics></axis>
    </joint>
    <!-- PLUGIN SENSOR: Ground Truth Odometry untuk Akuisisi Data -->
    <plugin
      filename="gz-sim-odometry-publisher-system"
      name="gz::sim::systems::OdometryPublisher">
      <odom_frame>world</odom_frame>
      <robot_base_frame>iris_5/base_link</robot_base_frame>
      <odom_publish_frequency>250</odom_publish_frequency>
      <dimensions>3</dimensions>
    </plugin>

    <!-- PLUGIN: MOTOR 0 (Front Right - CCW) -->
    <plugin filename="gz-sim-multicopter-motor-model-system" name="gz::sim::systems::MulticopterMotorModel">
      <jointName>rotor_0_joint</jointName>
      <linkName>rotor_0</linkName>
      <turningDirection>ccw</turningDirection>
      <timeConstantUp>0.02</timeConstantUp>
      <timeConstantDown>0.02</timeConstantDown>
      <maxRotVelocity>1100.0</maxRotVelocity>
      <motorConstant>8.54858e-06</motorConstant>
      <motorType>velocity</motorType>
      <momentConstant>0.016</momentConstant>
      <commandSubTopic>command/motor_speed</commandSubTopic>
      <actuator_number>0</actuator_number>
      <rotorDragCoefficient>0.000175</rotorDragCoefficient>
      <rollingMomentCoefficient>1e-06</rollingMomentCoefficient>
      <rotorVelocitySlowdownSim>10</rotorVelocitySlowdownSim>
    </plugin>

    <!-- PLUGIN: MOTOR 1 (Rear Left - CCW) -->
    <plugin filename="gz-sim-multicopter-motor-model-system" name="gz::sim::systems::MulticopterMotorModel">
      <jointName>rotor_1_joint</jointName>
      <linkName>rotor_1</linkName>
      <turningDirection>ccw</turningDirection>
      <timeConstantUp>0.02</timeConstantUp>
      <timeConstantDown>0.02</timeConstantDown>
      <maxRotVelocity>1100.0</maxRotVelocity>
      <motorConstant>8.54858e-06</motorConstant>
      <motorType>velocity</motorType>
      <momentConstant>0.016</momentConstant>
      <commandSubTopic>command/motor_speed</commandSubTopic>
      <actuator_number>1</actuator_number>
      <rotorDragCoefficient>0.000175</rotorDragCoefficient>
      <rollingMomentCoefficient>1e-06</rollingMomentCoefficient>
      <rotorVelocitySlowdownSim>10</rotorVelocitySlowdownSim>
    </plugin>

    <!-- PLUGIN: MOTOR 2 (Front Left - CW) -->
    <plugin filename="gz-sim-multicopter-motor-model-system" name="gz::sim::systems::MulticopterMotorModel">
      <jointName>rotor_2_joint</jointName>
      <linkName>rotor_2</linkName>
      <turningDirection>cw</turningDirection>
      <timeConstantUp>0.02</timeConstantUp>
      <timeConstantDown>0.02</timeConstantDown>
      <maxRotVelocity>1100.0</maxRotVelocity>
      <motorConstant>8.54858e-06</motorConstant>
      <motorType>velocity</motorType>
      <momentConstant>0.016</momentConstant>
      <commandSubTopic>command/motor_speed</commandSubTopic>
      <actuator_number>2</actuator_number>
      <rotorDragCoefficient>0.000175</rotorDragCoefficient>
      <rollingMomentCoefficient>1e-06</rollingMomentCoefficient>
      <rotorVelocitySlowdownSim>10</rotorVelocitySlowdownSim>
    </plugin>

    <!-- PLUGIN: MOTOR 3 (Rear Right - CW) -->
    <plugin filename="gz-sim-multicopter-motor-model-system" name="gz::sim::systems::MulticopterMotorModel">
      <jointName>rotor_3_joint</jointName>
      <linkName>rotor_3</linkName>
      <turningDirection>cw</turningDirection>
      <timeConstantUp>0.02</timeConstantUp>
      <timeConstantDown>0.02</timeConstantDown>
      <maxRotVelocity>1100.0</maxRotVelocity>
      <motorConstant>8.54858e-06</motorConstant>
      <motorType>velocity</motorType>
      <momentConstant>0.016</momentConstant>
      <commandSubTopic>command/motor_speed</commandSubTopic>
      <actuator_number>3</actuator_number>
      <rotorDragCoefficient>0.000175</rotorDragCoefficient>
      <rollingMomentCoefficient>1e-06</rollingMomentCoefficient>
      <rotorVelocitySlowdownSim>10</rotorVelocitySlowdownSim>
    </plugin>
  </model>
</sdf>
